Workbook

Sheet CCA
A1: COMPARABLE COMPANY ANALYSIS
C3: Market Data | I3: Financials | M3: Valuation
A5: Company | B5: Ticker | C5: Share Price | D5: Shares outstanding | E5: Equity Value | F5: Net Debt | G5: Enterprise Value | I5: Revenue | J5: EBITDA | K5: Net Income | M5: FORWARD EV/EBITDA | N5: FORWARD EV/REVENUE | O5: FORWARD P/E
A7: SRF Limited | B7: SRF | C7: 2736.8 | D7: =297444825/10000000 -> 29.744483 | E7: =C7*D7 -> 81404.7 | F7: =DATA!B21 -> 3008.12 | G7: =E7+F7 -> 84412.82 | I7: ='FORWARD No- FY26, FY27'!I24 -> 15786.51 | J7: ='FORWARD No- FY26, FY27'!I30 -> 3544.6194 | K7: ='FORWARD No- FY26, FY27'!I36 -> 1835.18 | M7: =G7/J7 -> 23.814353 | N7: =G7/I7 -> 5.3471489 | O7: =E7/K7 -> 44.357883
A8: Deepak Nitrite Limited | B8: DEEPAKNTR | C8: 1714.8 | D8: =136393041/10000000 -> 13.639304 | E8: =C8*D8 -> 23388.679 | F8: =DATA!B90 -> 860.45 | G8: =E8+F8 -> 24249.129 | I8: ='FORWARD No- FY26, FY27'!J24 -> 7887.07 | J8: ='FORWARD No- FY26, FY27'!J30 -> 1225.7418 | K8: ='FORWARD No- FY26, FY27'!J36 -> 550.66 | M8: =G8/J8 -> 19.783228 | N8: =G8/I8 -> 3.0745421 | O8: =E8/K8 -> 42.473902
A9: Aarti Industries Limited | B9: AARTIIND | C9: 500.75 | D9: =362519910/10000000 -> 36.251991 | E9: =C9*D9 -> 18153.184 | F9: =DATA!B44 -> 3552.82 | G9: =E9+F9 -> 21706.004 | I9: ='FORWARD No- FY26, FY27'!K24 -> 8286.1 | J9: ='FORWARD No- FY26, FY27'!K30 -> 1397.1909 | K9: ='FORWARD No- FY26, FY27'!K36 -> 419.06 | M9: =G9/J9 -> 15.535461 | N9: =G9/I9 -> 2.6195683 | O9: =E9/K9 -> 43.318819
A10: Vinati Organics Limited | B10: VINATIORGA | C10: 1325.2 | D10: =103665632/10000000 -> 10.366563 | E10: =C10*D10 -> 13737.77 | F10: =DATA!B159 -> 59.11 | G10: =E10+F10 -> 13796.88 | I10: ='FORWARD No- FY26, FY27'!L24 -> 2226.89 | J10: ='FORWARD No- FY26, FY27'!L30 -> 593.03052 | K10: ='FORWARD No- FY26, FY27'!L36 -> 443.74 | M10: =G10/J10 -> 23.265041 | N10: =G10/I10 -> 6.195582 | O10: =E10/K10 -> 30.959052
A11: Galaxy Surfactants Limited | B11: GALAXYSURF | C11: 1822.8 | D11: =35454752/10000000 -> 3.5454752 | E11: =C11*D11 -> 6462.6922 | F11: =DATA!B113 -> -5.56 | G11: =E11+F11 -> 6457.1322 | I11: ='FORWARD No- FY26, FY27'!M24 -> 5248.28 | J11: ='FORWARD No- FY26, FY27'!M30 -> 524.18715 | K11: ='FORWARD No- FY26, FY27'!M36 -> 267.38 | M11: =G11/J11 -> 12.318372 | N11: =G11/I11 -> 1.230333 | O11: =E11/K11 -> 24.17044
A12: Balaji Amines limited | B12: BALAMINES | C12: 1821 | D12: =32401000/10000000 -> 3.2401 | E12: =C12*D12 -> 5900.2221 | F12: =DATA!B67 -> -342.5 | G12: =E12+F12 -> 5557.7221 | I12: ='FORWARD No- FY26, FY27'!N24 -> 1428.98 | J12: ='FORWARD No- FY26, FY27'!N30 -> 300.95371 | K12: ='FORWARD No- FY26, FY27'!N36 -> 169.16 | M12: =G12/J12 -> 18.467033 | N12: =G12/I12 -> 3.8892931 | O12: =E12/K12 -> 34.879535
A13: Navin Floride international Limited | B13: NAVINFLUOR | C13: 7244.5 | D13: =49590125/10000000 -> 4.9590125 | E13: =C13*D13 -> 35925.566 | F13: =DATA!B136 -> 1425.87 | G13: =E13+F13 -> 37351.436 | I13: ='FORWARD No- FY26, FY27'!O24 -> 3313.9 | J13: ='FORWARD No- FY26, FY27'!O30 -> 742.70594 | K13: ='FORWARD No- FY26, FY27'!O36 -> 663.54 | M13: =G13/J13 -> 50.291016 | N13: =G13/I13 -> 11.271142 | O13: =E13/K13 -> 54.142276
A15: High | M15: =MAX(M8:M12) -> 23.265041 | N15: =MAX(N8:N12) -> 6.195582 | O15: =MAX(O8:O12) -> 43.318819
A16: 75th Percentile | M16: =QUARTILE(M8:M12,3) -> 19.783228 | N16: =QUARTILE(N8:N12,3) -> 3.8892931 | O16: =QUARTILE(O8:O12,3) -> 42.473902
A17: Average | M17: =AVERAGE(M8:M12) -> 17.873827 | N17: =AVERAGE(N8:N12) -> 3.4018637 | O17: =AVERAGE(O8:O12) -> 35.160349
A18: Median | M18: =MEDIAN(M8:M12) -> 18.467033 | N18: =MEDIAN(N8:N12) -> 3.0745421 | O18: =MEDIAN(O8:O12) -> 34.879535
A19: 25th percentile | M19: =QUARTILE(M8:M12,1) -> 15.535461 | N19: =QUARTILE(N8:N12,1) -> 2.6195683 | O19: =QUARTILE(O8:O12,1) -> 30.959052
A20: Low | M20: =MIN(M8:M12) -> 12.318372 | N20: =MIN(N8:N12) -> 1.230333 | O20: =MIN(O8:O12) -> 24.17044
A22: SRF Valuation | M22: EV/EBITDA | N22: EV/REVENUE | O22: P/E
A23: Implied Enterprise Value | M23: =M18*J7 -> 65458.604 | N23: =N18*I7 -> 48536.289 | O23: =O24+O25 -> 67018.345
A24: Net Debt | M24: =F7 -> 3008.12 | N24: =F7 -> 3008.12 | O24: =F7 -> 3008.12
A25: Implied Market value | M25: =M23-M24 -> 62450.484 | N25: =N23-N24 -> 45528.169 | O25: =O18*K7 -> 64010.225
A26: Shares Outstanding | M26: =D7 -> 29.744483 | N26: =D7 -> 29.744483 | O26: =D7 -> 29.744483
A27: Implied Value per share | M27: =M25/M26 -> 2099.5653 | N27: =N25/N26 -> 1530.6425 | O27: =O25/O26 -> 2152.0033

Sheet FORWARD No- FY26, FY27
A1: SRF LIMITED | H1: HISTORICAL REVENUE CAGR-3 YR (FY22-FY25)
A2: Years | B2: 44651 | C2: 45016 | D2: 45382 | E2: 45747 | H2: COMPANY | I2: SRF | J2: DEEPAKNTR | K2: AARTIIND | L2: VINATIORGA | M2: GALAXYSURF | N2: BALAMINES | O2: NAVINFLUOR
A3: Revenue | B3: 9953.44 | C3: 12073.84 | D3: 10786.67 | E3: 11697.97 | H3: CAGR | I3: =(E3/B3)^(1/3)-1 -> 0.055307683 | J3: =(E69/B69)^(1/3)-1 -> 0.067810693 | K3: =(E25/B25)^(1/3)-1 -> 0.06113855 | L3: =(E135/B135)^(1/3)-1 -> 0.11643984 | M3: =(E91/B91)^(1/3)-1 -> 0.046374719 | N3: =(E47/B47)^(1/3)-1 -> -0.1564353 | O3: =(E113/B113)^(1/3)-1 -> 0.1736178
A4: Raw Material Cost | B4: 4885.53 | C4: 5614.24 | D4: 5279.89 | E4: 5698.88
A5: Change in Inventory | B5: 193.25 | C5: -21.91 | D5: 114.32 | E5: -23.27
A6: Power and Fuel | B6: 984.23 | C6: 1230.86 | D6: 1134.9 | E6: 1127.06 | H6: HISTORICAL EBITDA MARGINS (FY22-FY25)
A7: Other Mfr. Exp | B7: 336.44 | C7: 371.99 | D7: 432.32 | E7: 455.86 | H7: COMPANY | I7: SRF | J7: DEEPAKNTR | K7: AARTIIND | L7: VINATIORGA | M7: GALAXYSURF | N7: BALAMINES | O7: NAVINFLUOR
A8: Employee Cost | B8: 658.77 | C8: 684.46 | D8: 790.54 | E8: 869.4 | H8: EBITDA MARGINS | I8: =AVERAGE(B18:E18) -> 0.22453471 | J8: =AVERAGE(B84:E84) -> 0.15541155 | K8: =AVERAGE(B40:E40) -> 0.16861864 | L8: =AVERAGE(B150:E150) -> 0.26630436 | M8: =AVERAGE(B106:E106) -> 0.099877894 | N8: =AVERAGE(B62:E62) -> 0.21060736 | O8: =AVERAGE(B128:E128) -> 0.22411839
A9: Selling and admin | B9: 556.23 | C9: 602.3 | D9: 520.46 | E9: 641.8
A10: Other Expenses | B10: 192.08 | C10: 354.02 | D10: 352.97 | E10: 425.98
A11: Depreciation | B11: 419.23 | C11: 468.44 | D11: 555.85 | E11: 629.96 | H11: HISTORICAL PAT MARGINS (FY22-FY25)
A12: Interest | B12: 94.45 | C12: 175.82 | D12: 235.6 | E12: 296.35 | H12: COMPANY | I12: SRF | J12: DEEPAKNTR | K12: AARTIIND | L12: VINATIORGA | M12: GALAXYSURF | N12: BALAMINES | O12: NAVINFLUOR
A13: Tax | B13: 648.03 | C13: 632.5 | D13: 343.85 | E13: 436.31 | H13: PAT MARGINS | I13: =AVERAGE(B19:E19) -> 0.19576625 | J13: =AVERAGE(B85:E85) -> 0.13597124 | K13: =AVERAGE(B41:E41) -> 0.14532952 | L13: =AVERAGE(B151:E151) -> 0.23507528 | M13: =AVERAGE(B107:E107) -> 0.081968098 | N13: =AVERAGE(B63:E63) -> 0.19031594 | O13: =AVERAGE(B129:E129) -> 0.2049482
A15: EBITDA | B15: =B3-B4-B5-B6-B7-B8-B9-B10 -> 2146.91 | C15: =C3-C4-C5-C6-C7-C8-C9-C10 -> 3237.88 | D15: =D3-D4-D5-D6-D7-D8-D9-D10 -> 2161.27 | E15: =E3-E4-E5-E6-E7-E8-E9-E10 -> 2502.26
A16: EBT | B16: =IFERROR(B15-SUM(B11-B12),0) -> 1822.13 | C16: =IFERROR(C15-SUM(C11-C12),0) -> 2945.26 | D16: =IFERROR(D15-SUM(D11-D12),0) -> 1841.02 | E16: =IFERROR(E15-SUM(E11-E12),0) -> 2168.65
A17: PAT | B17: =B16-B13 -> 1174.1 | C17: =C16-C13 -> 2312.76 | D17: =D16-D13 -> 1497.17 | E17: =E16-E13 -> 1732.34 | H17: FY26 - FY27 GROWTH RATE PROJECTION
A18: EBITDA MARGIN | B18: =(B15/B3) -> 0.21569528 | C18: =(C15/C3) -> 0.26817317 | D18: =(D15/D3) -> 0.20036489 | E18: =(E15/E3) -> 0.21390549 | H18: COMPANY | I18: SRF | J18: DEEPAKNTR | K18: AARTIIND | L18: VINATIORGA | M18: GALAXYSURF | N18: BALAMINES | O18: NAVINFLUOR
A19: PAT MARGIN | B19: =B16/B3 -> 0.18306535 | C19: =C16/C3 -> 0.24393731 | D19: =D16/D3 -> 0.17067547 | E19: =E16/E3 -> 0.18538687 | H19: GROWTH RATE | I19: =9% -> 0.09 | J19: 0.06 | K19: 0.12 | L19: 0.08 | M19: =8% -> 0.08 | N19: =10% -> 0.1 | O19: 0.15
H20: ACTUAL RATE | I20: =(I24/E3)-1 -> 0.3495085 | J20: =(J24/E69)-1 -> -0.047677293 | K20: =(K24/E25)-1 -> 0.13955925 | L20: =(L24/E135)-1 -> -0.0094346337 | M20: =(M24/E91)-1 -> 0.24340012 | N20: =(N24/E47)-1 -> 0.028931452 | O20: =(O24/E113)-1 -> 0.41054236
H22: FY26 - FY27 REVENUE PROJECTION
A23: AARTI INDUSTRIES LTD | H23: COMPANY | I23: SRF | J23: DEEPAKNTR | K23: AARTIIND | L23: VINATIORGA | M23: GALAXYSURF | N23: BALAMINES | O23: NAVINFLUOR
A24: Years | B24: 44651 | C24: 45016 | D24: 45382 | E24: 45747 | H24: FY26 | I24: 15786.51 | J24: 7887.07 | K24: 8286.1 | L24: 2226.89 | M24: 5248.28 | N24: 1428.98 | O24: 3313.9
A25: Revenue | B25: 6085.51 | C25: 6618.58 | D25: 6370.8 | E25: 7271.32 | H25: FY27 | I25: =I24*(1+I19) -> 17207.296 | J25: =J24*(1+J19) -> 8360.2942 | K25: =K24*(1+K19) -> 9280.432 | L25: =L24*(1+L19) -> 2405.0412 | M25: =M24*(1+M19) -> 5668.1424 | N25: =N24*(1+N19) -> 1571.878 | O25: =O24*(1+O19) -> 3810.985
A26: Raw Material Cost | B26: 2599.63 | C26: 3195.54 | D26: 3578.8 | E26: 4166.72
A27: Change in Inventory | B27: 210.49 | C27: -65.7 | D27: 93.57 | E27: -54.03
A28: Power and Fuel | B28: 131.89 | C28: 160.83 | D28: 170.52 | E28: 175.61 | H28: FY26 - FY27 EBITDA PROJECTION
A29: Other Mfr. Exp | B29: 1064.42 | C29: 1272.55 | D29: 1001.49 | E29: 978.99 | H29: COMPANY | I29: SRF | J29: DEEPAKNTR | K29: AARTIIND | L29: VINATIORGA | M29: GALAXYSURF | N29: BALAMINES | O29: NAVINFLUOR
A30: Employee Cost | B30: 356.96 | C30: 385.33 | D30: 403.74 | E30: 422.42 | H30: FY26 | I30: =I24*I8 -> 3544.6194 | J30: =J24*J8 -> 1225.7418 | K30: =K24*K8 -> 1397.1909 | L30: =L24*L8 -> 593.03052 | M30: =M24*M8 -> 524.18715 | N30: =N24*N8 -> 300.95371 | O30: =O24*O8 -> 742.70594
A31: Selling and admin | B31: 410.21 | C31: 432.5 | D31: 312.08 | E31: 439.44 | H31: FY27 | I31: =I25*I8 -> 3863.6352 | J31: =J25*J8 -> 1299.2863 | K31: =K25*K8 -> 1564.8538 | L31: =L25*L8 -> 640.47296 | M31: =M25*M8 -> 566.12213 | N31: =N25*N8 -> 331.04908 | O31: =O25*O8 -> 854.11183
A32: Other Expenses | B32: 12.78 | C32: 17.16 | D32: 19.6 | E32: 33.66
A33: Depreciation | B33: 246.4 | C33: 310.45 | D33: 378.12 | E33: 434.27
A34: Interest | B34: 102.33 | C34: 168.28 | D34: 211.47 | E34: 275.44 | H34: FY26 - FY27 PAT PROJECTION
A35: Tax | B35: 186.25 | C35: 65.87 | D35: -21.05 | E35: -23.64 | H35: COMPANY | I35: SRF | J35: DEEPAKNTR | K35: AARTIIND | L35: VINATIORGA | M35: GALAXYSURF | N35: BALAMINES | O35: NAVINFLUOR
H36: FY26 | I36: 1835.18 | J36: 550.66 | K36: 419.06 | L36: 443.74 | M36: 267.38 | N36: 169.16 | O36: 663.54
A37: EBITDA | B37: =B25-B26-B27-B28-B29-B30-B31-B32 -> 1299.13 | C37: =C25-C26-C27-C28-C29-C30-C31-C32 -> 1220.37 | D37: =D25-D26-D27-D28-D29-D30-D31-D32 -> 791 | E37: =E25-E26-E27-E28-E29-E30-E31-E32 -> 1108.51 | H37: FY27 | I37: =I25*I13 -> 3368.6078 | J37: =J25*J13 -> 1136.7595 | K37: =K25*K13 -> 1348.7208 | L37: =L25*L13 -> 565.36573 | M37: =M25*M13 -> 464.60685 | N37: =N25*N13 -> 299.15344 | O37: =O25*O13 -> 781.05451
A38: EBT | B38: =IFERROR(B37-SUM(B33-B34),0) -> 1155.06 | C38: =IFERROR(C37-SUM(C33-C34),0) -> 1078.2 | D38: =IFERROR(D37-SUM(D33-D34),0) -> 624.35 | E38: =IFERROR(E37-SUM(E33-E34),0) -> 949.68
A39: PAT | B39: =B38-B35 -> 968.81 | C39: =C38-C35 -> 1012.33 | D39: =D38-D35 -> 645.4 | E39: =E38-E35 -> 973.32
A40: EBITDA MARGIN | B40: =(B37/B25) -> 0.21347923 | C40: =(C37/C25) -> 0.18438547 | D40: =(D37/D25) -> 0.12416023 | E40: =(E37/E25) -> 0.15244962
A41: PAT MARGIN | B41: =B38/B25 -> 0.18980496 | C41: =C38/C25 -> 0.16290503 | D41: =D38/D25 -> 0.098001821 | E41: =E38/E25 -> 0.13060627
A45: BALAJI AMINES LTD
...

Sheet DATA
A1: SRF LIMITED
A2: PROFIT & LOSS | B2: 45747
A3: Sales | B3: 11697.97
A4: Raw Material Cost | B4: 5698.88
A5: Change in Inventory | B5: -23.27
A6: Power and Fuel | B6: 1127.06
A7: Other Mfr. Exp | B7: 455.86
A8: Employee Cost | B8: 869.4
A9: Selling and admin | B9: 641.8
A10: Other Expenses | B10: 425.98
A11: Depreciation | B11: 629.96
A12: Interest | B12: 296.35
A13: Tax | B13: 436.31
... A15: Cash & Bank | B15: 329.1
A17: EBITDA | B17: =B3-B4-(B5)-B6-B7-B8-B9-B10 -> 2502.26
A18: EBT | B18: =B17-B11-B12 -> 1575.95
A19: NET INCOME/ PAT | B19: =B18-B13 -> 1139.64
A20: REVENUE | B20: =B3 -> 11697.97
A21: NET DEBT | B21: =B14-B15 -> 3008.12
A24: AARTI INDUSTRIES LTD
A25: PROFIT & LOSS | B25: 45747
A26: Sales | B26: 7271.32
A27: Raw Material Cost | B27: 4166.72
A28: Change in Inventory | B28: -54.03
A29: Power and Fuel | B29: 175.61
A30: Other Mfr. Exp | B30: 978.99
A31: Employee Cost | B31: 422.42
A32: Selling and admin | B32: 439.44
A33: Other Expenses | B33: 33.66
A34: Depreciation | B34: 434.27
A35: Interest | B35: 275.44
A36: Tax | B36: -23.64
... A38: Cash & Bank | B38: 294.97
A40: EBITDA | B40: =B26-B27-(B28)-B29-B30-B31-B32-B33 -> 1108.51
A41: EBT | B41: =B40-B34-B35 -> 398.8
A42: NET INCOME/ PAT | B42: =B41-(B36) -> 422.44
A43: REVENUE | B43: =B26 -> 7271.32
A44: NET DEBT | B44: =B37-B38 -> 3552.82
A47: BALAJI AMINES LTD
A48: PROFIT & LOSS | B48: 45747
...
